Workbook
Name APPLICANTS_PER_YEAR: Assumptions!$C$34
Name BASE_CONVERSION: Assumptions!$C$30
Name BASE_RETENTION: Assumptions!$C$29
Name CAP_DOWN: Assumptions!$C$26
Name CAP_UP: Assumptions!$C$25
Name COMMISSION_NB: Assumptions!$C$11
Name COMMISSION_RN: Assumptions!$C$12
Name CONV_CEIL: Assumptions!$C$39
Name CONV_FLOOR: Assumptions!$C$38
Name CURRENT_FLAT: Assumptions!$C$27
Name ELAST_INCREASE: Assumptions!$C$32
Name ELAST_MARKET: Assumptions!$C$31
Name EXPECTED_NB_SHARE: Assumptions!$C$16
Name FIXED_BLENDED: Assumptions!$C$22
Name FIXED_PER_POLICY: Assumptions!$C$14
Name GRAD_CONTINUE: Assumptions!$C$35
Name GROSS_MULT: Assumptions!$C$21
Name LAE_RATIO: Assumptions!$C$8
Name LOSS_TREND: Assumptions!$C$6
Name MARKET_RISK_WEIGHT: Assumptions!$C$33
Name NB_ACQUISITION: Assumptions!$C$15
Name OTHER_VARIABLE: Assumptions!$C$10
Name PERMISSIBLE: Assumptions!$C$19
Name POLICY_FEE: Assumptions!$C$23
Name PREMIUM_TAX: Assumptions!$C$9
Name PROFIT_LOAD: Assumptions!$C$13
Name RET_CEIL: Assumptions!$C$37
Name RET_FLOOR: Assumptions!$C$36
Name TREND_FACTOR: Assumptions!$C$20
Name TREND_YEARS: Assumptions!$C$7
Name VAR_EXPENSE: Assumptions!$C$18

Sheet README
B2: ABG Dormitory Insurance — Pricing, Dislocation & Business Plan
B6: WHAT THIS IS
C7: A working rating and business-plan model. Change any assumption and every table, premium, dislocation figure and pro forma line recalculates.
B9: TAB GUIDE
B10: Assumptions | C10: Every lever. Yellow cells are the ones to edit. It also contains market sensitivity analsyis for the 3 plans with varying price elasticity and competitor behaviour.
B11: ModelOutput | C11: GLM output: base loss costs by tier, and the rating factors. Blue = pasted from Python.
B12: RateBuildup | C12: Loss cost -> premium: trend, claims handling, expenses, profit, policy fee.
B13: QuoteCalc | C13: Pick a student from the dropdowns and watch the premium build up coverage by coverage.
B14: Segments | C14: The engine. All 400 segments, each with its factors, loss cost and indicated premium.
B15: Dislocation | C15: Who pays more, who pays less, and what capping the change costs.
B16: ProFormaA/B/C | C16: Three-year business plan under each strategy. A = keep flat rate, B = new plan with +/-25% caps, C = new plan capping increases only.
B17: PlanCompare | C17: The three plans side by side.
B19: COLOR LEGEND
B20: Blue text | C20: Hardcoded input or model output. Safe to change only if you know the source.
B21: Black text | C21: Formula. Do not overwrite.
B22: Green text | C22: Link to another tab.
B23: Yellow fill | C23: Key assumptions: Edittable Cells
B25: KEY ASSUMPTIONS
C26: 1. Exposure is ONE policy-year per student. Verified: class and GPA are single-valued per student, and the data has no time dimension.
C27: 2. Today's flat premium (CURRENT_FLAT) is NOT given in the case. It defaults to the new plan's own average, which makes the rollout revenue-neutral.
C28: 3. All expense, trend and market figures are cited values
C29: 4. The indicated premium is far above typical renters insurance (~$150-270/yr) because ABG's product is much richer ($150k guest medical vs $1-5k market) and dorm frequency runs high.
B32: PRO FORMA TABS — HOW THE COLUMNS WORK
C33: The three ProForma tabs are identical except for one column (Charged — renewal). Each projects the book forward three years at segment level.
B34: Columns A-J | C34: Segment keys, tier, class adjustment, year-0 student count, and base loss cost all linked from Segments. Column J is the offset 0-4 within the group; every ageing formula switches on it.
B36: YEAR BLOCK — 14 COLUMNS, IN CALCULATION ORDER
B37: Prev premium | C37: What this cohort paid last year. Year 1 = CURRENT_FLAT. Freshmen have no renewals, so theirs is set to the indicated premium.
B38: Loss cost (trended) | C38: Base loss cost inflated to the projection year at LOSS_TREND.
B39: Indicated premium | C39: Loss cost x GROSS_MULT + POLICY_FEE.
B40: Market price | C40: What a competitor would charge: a blend of our indicated premium and a flat price, weighted by MARKET_RISK_WEIGHT.
B41: Charged — renewal | C41: The renewal premium for this year
B42: Retention | C42: Base renewal rate, less a penalty for pricing above market, less a rate-shock penalty for a large increase. Clamped between RET_FLOOR and RET_CEIL.
B43: Conversion | C43: Same shape for new business, but only the market term. A new applicant has no prior premium, so no rate shock applies.
B44: Renewal policies | C44: The ageing engine. Offset 0 (Freshman): zero, nobody ages into Freshman. Offsets 1-3: the row above, i.e. the class below them last year. Offset 4 (Grad): itself, x GRAD_CONTINUE. Seniors never appear as a source — that is how graduation is modelled. Retention is applied after ageing, so it reflects the price at the new class and tier.
B45: New policies | C45: The applicant funnel mirrors the current book's segment mix (segment students / 10,000), scaled to APPLICANTS_PER_YEAR, times conversion. New business enters at its own class, not aged.
B46: Total policies | C46: Renewals + new business.
B47: Avg charged | C47: Policy-weighted blend of what renewals and new business actually paid. This becomes next year's prior premium.
B48: Written premium | C48: Renewals at the capped rate + new business at the indicated rate.
... B50: Expenses | C50: Four terms: renewals x charged x (tax + other + renewal commission), plus new x indicated x (tax + other + NB commission), plus all policies x fixed expense, plus new x acquisition cost. New business is dearer on both counts — this is the new-vs-renewal cost difference the case asks about.
B52: YEARS 2 AND 3
...

Sheet Assumptions
B2: Assumptions
B3: Yellow cells are inputs. White cells with black text are derived — do not overwrite.
B5: PRICING | F5: MARKET SENSITIVITY: 3-year underwriting profit
B6: Annual loss-cost trend | C6: 0.03 | D6: Placeholder. Source needed (e.g. CPI medical + electronics).
B7: Years: experience mid -> policy mid | C7: 1.5 | D7: Experience period midpoint to first policy year midpoint.
B8: Loss adjustment expense (% of loss) | C8: 0.12 | D8: Claims handling. TX filing gives loss+LAE combined only.
B9: Premium tax (% of premium) | C9: 0.018 | D9: Allstate TX REN filing, Attachment I Exhibit 2: 1.8%. | F9: A. Keep flat rate | G9: Competitors flat | H9: Half risk-based | I9: Fully risk-based
B10: Other variable expense (% of premium) | C10: 0.091 | D10: TX filing: licenses/fees 0.2% + other acq 4.7% + general 4.2%. | F10: =PlanCompare!C10 -> -8687023.9 | G10: 0 | H10: 0.5 | I10: 1
B11: Commission — new business | C11: 0.115 | D11: TX filing Exhibit 2 gives 11.5% blended; NB/RN split is assumed. | F11: 0 | G11: 4030441.9 | H11: 4030441.9 | I11: 4030441.9
B12: Commission — renewal | C12: 0.08 | D12: Assumed lower than new business. | F12: 0.25 | G12: 4030441.9 | H12: -3121800.9 | I12: -8664773.7
B13: Underwriting profit & contingency | C13: 0.077 | D13: TX filing Attachment II p.9 step (15): 7.7%. | F13: 0.5 | G13: 4030441.9 | H13: -8687023.9 | I13: -13253530
B14: Fixed expense ($ per policy-year) | C14: 20 | D14: Overhead / policy admin. Placeholder — filing is % based. | F14: 1 | G14: 4030441.9 | H14: -14723742 | I14: -17245062
B15: Acquisition cost ($ per NEW policy) | C15: 25 | D15: One-time marketing cost. Placeholder.
B16: Expected new-business share of book | C16: 0.4 | D16: Used to blend commission and fixed cost into the filed rate. | F16: B. New plan, +/-25% caps | G16: Competitors flat | H16: Half risk-based | I16: Fully risk-based
B17: DERIVED — do not edit | F17: =PlanCompare!D10 -> 1548746.7 | G17: 0 | H17: 0.5 | I17: 1
B18: Variable expense V | C18: =PREMIUM_TAX+OTHER_VARIABLE+EXPECTED_NB_SHARE*COMMISSION_NB+(1-EXPECTED_NB_SHARE)*COMMISSION_RN -> 0.203 | D18: Tax + other + blended commission. | F18: 0 | G18: 3262189.7 | H18: 3262189.7 | I18: 3262189.7
B19: Permissible loss ratio (1 - V - Q) | C19: =1-VAR_EXPENSE-PROFIT_LOAD -> 0.72 | D19: Share of premium available for loss + LAE. | F19: 0.25 | G19: 2659875 | H19: 2157694.1 | I19: 2282637.2
B20: Trend factor | C20: =(1+LOSS_TREND)^TREND_YEARS -> 1.0453358 | D20: Brings experience losses to the policy period. | F20: 0.5 | G20: 3090664.5 | H20: 1548746.7 | I20: 1786279.6
B21: Gross multiplier | C21: =TREND_FACTOR*(1+LAE_RATIO)/PERMISSIBLE -> 1.626078 | D21: Trend x (1+LAE) / permissible. | F21: 1 | G21: 3777631.2 | H21: 1359203.8 | I21: 1584661.4
B22: Blended fixed cost per policy | C22: =FIXED_PER_POLICY+EXPECTED_NB_SHARE*NB_ACQUISITION -> 30 | D22: Fixed + expected share of acquisition.
B23: Policy fee (flat, per policy) | C23: =FIXED_BLENDED/PERMISSIBLE -> 41.666667 | D23: Fixed Expense/Permissible loss ratio | F23: C. New plan, cap increases only | G23: Competitors flat | H23: Half risk-based | I23: Fully risk-based
B24: TRANSITION | F24: =PlanCompare!E10 -> 540129.12 | G24: 0 | H24: 0.5 | I24: 1
B25: Max renewal increase per year | C25: 0.25 | D25: Capped rate on the way up. | F25: 0 | G25: 1953151.1 | H25: 1953151.1 | I25: 1953151.1
B26: Max renewal decrease per year | C26: 0.25 | D26: Capped rate on the way down. | F26: 0.25 | G26: 1303793.4 | H26: 1013667.8 | I26: 1451655.1
B27: Today's flat premium (per student-year) | C27: =Segments!$AH$1 -> 1426.2298 | D27: NOT GIVEN IN THE CASE. Defaults to the indicated average (revenue-neutral). | F27: 0.5 | G27: 1693070.7 | H27: 540129.12 | I27: 1374062.6
B28: MARKET & RETENTION | F28: 1 | G28: 2416561.7 | H28: 560016.17 | I28: 1381031.4
B29: Base renewal rate at market price | C29: 0.85
B30: Base quote-to-bind rate at market | C30: 0.35 | F30: NEW PLAN (B) MINUS FLAT RATE (A)
B31: Retention drop per +100% vs market | C31: 0.5 | D31: Price elasticity. | F31: Price sensitivity | G31: Competitors flat | H31: Half risk-based | I31: Fully risk-based
B32: Extra retention drop per +100% increase | C32: 0.3 | D32: Rate-shock effect, on top of price-vs-market. | F32: =F18 -> 0 | G32: =G18-G11 -> -768252.19 | H32: =H18-H11 -> -768252.19 | I32: =I18-I11 -> -768252.19
B33: How risk-based competitors are | C33: 0.5 | D33: 0 = competitors charge flat like ABG today; 1 = fully risk-based. | F33: =F19 -> 0.25 | G33: =G19-G12 -> -1370566.9 | H33: =H19-H12 -> 5279495 | I33: =I19-I12 -> 10947411
B34: Applicants per year | C34: 12000 | D34: New-business applicants | F34: =F20 -> 0.5 | G34: =G20-G13 -> -939777.4 | H34: =H20-H13 -> 10235771 | I34: =I20-I13 -> 15039810
B35: Grad students still enrolled next year | C35: 0.5 | D35: Probability of grads being enrolled | F35: =F21 -> 1 | G35: =G21-G14 -> -252810.72 | H35: =H21-H14 -> 16082946 | I35: =I21-I14 -> 18829723
B36: Retention floor | C36: 0.3
B37: Retention ceiling | C37: 0.95 | F37: New plan (B) profitable in | G37: =COUNTIF(G18:I21,">0")&" of 12 scenarios" -> 12 of 12 scenarios
B38: Conversion floor | C38: 0.02 | F38: Flat rate (A) profitable in | G38: =COUNTIF(G11:I14,">0")&" of 12 scenarios" -> 6 of 12 scenarios
B39: Conversion ceiling | C39: 0.9 | F39: Plan C profitable in | G39: =COUNTIF(G25:I28,">0")&" of 12 scenarios" -> 12 of 12 scenarios
F41: Notes: Based on existing assumptions, policyholders are insensitive to price plan A dominates. When competitors charge flat premiums for all policyholders plan A also dominates.

Sheet ModelOutput
B2: Model Output — from the M5 frequency x severity GLM
B3: BLUE = pasted from Python. To change these, refit the model in the notebook and repaste.
B4: Model: Poisson frequency x Gamma severity, GM/Liability capped at $50k per claim, rebalanced and loaded back to uncapped. Fit on all 10,000 students.
B6: BASE LOSS COST BY TIER AND COVERAGE ($ per policy-year)
B7: Base risk profile: | C7: Freshman / Junior / Senior (tier base class), Non-greek, on campus, sprinklered, GPA 2.0-3.0
B8: Tier | C8: Base class | D8: Personal Property | E8: Additional Living Expense | F8: Guest Medical | G8: Liability | H8: Total
B9: Tier 1 | C9: Freshman | D9: 36.175497 | E9: 106.64708 | F9: 123.72648 | G9: 20.551544 | H9: =SUM(D9:G9) -> 287.10061
B10: Tier 2 | C10: Junior | D10: 42.805151 | E10: 126.19162 | F10: 146.40105 | G10: 24.317895 | H10: =SUM(D10:G10) -> 339.71571
B11: Tier 3 | C11: Senior | D11: 40.009437 | E11: 117.94972 | F11: 136.83923 | G11: 22.729632 | H11: =SUM(D11:G11) -> 317.52802
B13: RATING FACTORS (multiplicative, versus the base level within each coverage)
B15: Variable | C15: Level | D15: Personal Property | E15: Additional Living Expense | F15: Guest Medical | G15: Liability | H15: Base level (factor = 1.00)
B16: class_adj | C16: Sophomore | D16: 0.98982624 | E16: 0.98982624 | F16: 0.98982624 | G16: 0.98982624 | H16: Base (Freshman/Junior/Senior)
B17: class_adj | C17: Grad | D17: 1.1906804 | E17: 1.1906804 | F17: 1.1906804 | G17: 1.1906804 | H17: Base (Freshman/Junior/Senior)
B18: greek | C18: Greek | D18: 4.3562312 | E18: 4.3562312 | F18: 4.3562312 | G18: 4.3562312 | H18: Non-greek
B19: dist_band | C19: Off 0-1mi | D19: 1.9771404 | E19: 1.9459582 | F19: 2.5135188 | G19: 3.1684506 | H19: On campus
B20: dist_band | C20: Off 1-3mi | D20: 1.700622 | E20: 1.6738008 | F20: 2.1619837 | G20: 2.7253181 | H20: On campus
B21: dist_band | C21: Off 3-6mi | D21: 1.9507742 | E21: 1.9200078 | F21: 2.4799997 | G21: 3.1261976 | H21: On campus
B22: dist_band | C22: Off 6+mi | D22: 2.2239289 | E22: 2.1888545 | F22: 2.8272586 | G22: 3.5639395 | H22: On campus
B23: spr | C23: No | D23: 1.5400748 | E23: 1.5400748 | F23: 1.5400748 | G23: 1.5400748 | H23: Yes (sprinklered)
B24: gpa_band | C24: <1.0 | D24: 1.121448 | E24: 1.121448 | F24: 1.121448 | G24: 1.121448 | H24: 2.0-3.0
B25: gpa_band | C25: 1.0-2.0 | D25: 1.0176256 | E25: 1.0176256 | F25: 1.0176256 | G25: 1.0176256 | H25: 2.0-3.0
B26: gpa_band | C26: 3.0+ | D26: 0.87654762 | E26: 0.87654762 | F26: 0.87654762 | G26: 0.87654762 | H26: 2.0-3.0

Sheet RateBuildup
B2: Rate Build-up — from loss cost to filed premium
B3: Premium = (loss cost x trend x (1+LAE)) / (1 - V - Q) + policy fee
B5: STEP 1 — EXPENSE AND PROFIT PROVISIONS
B6: Premium tax | C6: =PREMIUM_TAX -> 0.018 | D6: % of premium
B7: Other variable expense | C7: =OTHER_VARIABLE -> 0.091 | D7: Licenses, other acquisition, general expense
B8: Commission (blended NB/RN) | C8: =EXPECTED_NB_SHARE*COMMISSION_NB+(1-EXPECTED_NB_SHARE)*COMMISSION_RN -> 0.094 | D8: Weighted by the expected new book share
B9: Total variable expense V | C9: =VAR_EXPENSE -> 0.203 | D9: Sum of the three above
B10: Underwriting profit & contingency Q | C10: =PROFIT_LOAD -> 0.077 | D10: Target return
B11: Permissible loss ratio (1 - V - Q) | C11: =PERMISSIBLE -> 0.72 | D11: Share of premium left for loss + LAE
B13: STEP 2 — LOSS LOADINGS
B14: Trend factor | C14: =TREND_FACTOR -> 1.0453358 | D14: (1 + annual trend) ^ years
B15: Loss adjustment expense | C15: =LAE_RATIO -> 0.12 | D15: % of loss
B16: Loss cost -> premium multiplier | C16: =GROSS_MULT -> 1.626078 | D16: Trend x (1+LAE) / permissible
B17: Policy fee | C17: =POLICY_FEE -> 41.666667 | D17: Fixed expense / permissible — flat per policy
B19: STEP 3 — GROSS BASE RATES BY TIER AND COVERAGE ($ per policy-year)
B20: Tier | C20: Personal Property | D20: Additional Living Expense | E20: Guest Medical | F20: Liability | G20: Policy fee | H20: Base policy total
B21: Tier 1 | C21: =ModelOutput!$D$9*GROSS_MULT -> 58.824178 | D21: =ModelOutput!$E$9*GROSS_MULT -> 173.41647 | E21: =ModelOutput!$F$9*GROSS_MULT -> 201.18891 | F21: =ModelOutput!$G$9*GROSS_MULT -> 33.418413 | G21: =POLICY_FEE -> 41.666667 | H21: =SUM(C21:G21) -> 508.51464
B22: Tier 2 | C22: =ModelOutput!$D$10*GROSS_MULT -> 69.604512 | D22: =ModelOutput!$E$10*GROSS_MULT -> 205.19741 | E22: =ModelOutput!$F$10*GROSS_MULT -> 238.05952 | F22: =ModelOutput!$G$10*GROSS_MULT -> 39.542793 | G22: =POLICY_FEE -> 41.666667 | H22: =SUM(C22:G22) -> 594.0709
B23: Tier 3 | C23: =ModelOutput!$D$11*GROSS_MULT -> 65.058464 | D23: =ModelOutput!$E$11*GROSS_MULT -> 191.79545 | E23: =ModelOutput!$F$11*GROSS_MULT -> 222.51125 | F23: =ModelOutput!$G$11*GROSS_MULT -> 36.960153 | G23: =POLICY_FEE -> 41.666667 | H23: =SUM(C23:G23) -> 557.99198
B25: These are the rates for the BASE risk in each tier. The factors from the ModelOutput tab then move an individual student up or down

Sheet QuoteCalc
B2: Quote Calculator — price a single student
B5: STUDENT PROFILE
B6: Class | C6: Junior
B7: Greek status | C7: Non-greek
B8: Distance band | C8: On campus
B9: Sprinklered | C9: Yes
B10: GPA band | C10: 3.0+
B12: Tier (derived from class) | C12: =IF(OR($C$6="Freshman",$C$6="Sophomore"),1,IF($C$6="Junior",2,3)) -> 2
B13: Class adjustment | C13: =IF($C$6="Sophomore","Sophomore",IF($C$6="Grad student","Grad","Base")) -> Base
B15: PREMIUM BUILD-UP BY COVERAGE
B16: Step | C16: Source | D16: Personal Property | E16: Additional Living Expense | F16: Guest Medical | G16: Liability | H16: Total
B17: Base loss cost (tier) | C17: ModelOutput | D17: =INDEX(ModelOutput!$D$9:$D$11,MATCH("Tier "&$C$12,ModelOutput!$B$9:$B$11,0)) -> 42.805151 | E17: =INDEX(ModelOutput!$E$9:$E$11,MATCH("Tier "&$C$12,ModelOutput!$B$9:$B$11,0)) -> 126.19162 | F17: =INDEX(ModelOutput!$F$9:$F$11,MATCH("Tier "&$C$12,ModelOutput!$B$9:$B$11,0)) -> 146.40105 | G17: =INDEX(ModelOutput!$G$9:$G$11,MATCH("Tier "&$C$12,ModelOutput!$B$9:$B$11,0)) -> 24.317895
B18: x Class factor | C18: ModelOutput | D18: =IF($C$13="Base",1,INDEX(ModelOutput!$D$16:$D$26,MATCH($C$13,ModelOutput!$C$16:$C$26,0))) -> 1 | E18: =IF($C$13="Base",1,INDEX(ModelOutput!$E$16:$E$26,MATCH($C$13,ModelOutput!$C$16:$C$26,0))) -> 1 | F18: =IF($C$13="Base",1,INDEX(ModelOutput!$F$16:$F$26,MATCH($C$13,ModelOutput!$C$16:$C$26,0))) -> 1 | G18: =IF($C$13="Base",1,INDEX(ModelOutput!$G$16:$G$26,MATCH($C$13,ModelOutput!$C$16:$C$26,0))) -> 1
B19: x Greek factor | C19: ModelOutput | D19: =IF($C$7="Non-greek",1,INDEX(ModelOutput!$D$16:$D$26,MATCH($C$7,ModelOutput!$C$16:$C$26,0))) -> 1 | E19: =IF($C$7="Non-greek",1,INDEX(ModelOutput!$E$16:$E$26,MATCH($C$7,ModelOutput!$C$16:$C$26,0))) -> 1 | F19: =IF($C$7="Non-greek",1,INDEX(ModelOutput!$F$16:$F$26,MATCH($C$7,ModelOutput!$C$16:$C$26,0))) -> 1 | G19: =IF($C$7="Non-greek",1,INDEX(ModelOutput!$G$16:$G$26,MATCH($C$7,ModelOutput!$C$16:$C$26,0))) -> 1
B20: x Distance factor | C20: ModelOutput | D20: =IF($C$8="On campus",1,INDEX(ModelOutput!$D$16:$D$26,MATCH($C$8,ModelOutput!$C$16:$C$26,0))) -> 1 | E20: =IF($C$8="On campus",1,INDEX(ModelOutput!$E$16:$E$26,MATCH($C$8,ModelOutput!$C$16:$C$26,0))) -> 1 | F20: =IF($C$8="On campus",1,INDEX(ModelOutput!$F$16:$F$26,MATCH($C$8,ModelOutput!$C$16:$C$26,0))) -> 1 | G20: =IF($C$8="On campus",1,INDEX(ModelOutput!$G$16:$G$26,MATCH($C$8,ModelOutput!$C$16:$C$26,0))) -> 1
B21: x Sprinkler factor | C21: ModelOutput | D21: =IF($C$9="Yes",1,INDEX(ModelOutput!$D$16:$D$26,MATCH($C$9,ModelOutput!$C$16:$C$26,0))) -> 1 | E21: =IF($C$9="Yes",1,INDEX(ModelOutput!$E$16:$E$26,MATCH($C$9,ModelOutput!$C$16:$C$26,0))) -> 1 | F21: =IF($C$9="Yes",1,INDEX(ModelOutput!$F$16:$F$26,MATCH($C$9,ModelOutput!$C$16:$C$26,0))) -> 1 | G21: =IF($C$9="Yes",1,INDEX(ModelOutput!$G$16:$G$26,MATCH($C$9,ModelOutput!$C$16:$C$26,0))) -> 1
B22: x GPA factor | C22: ModelOutput | D22: =IF($C$10="2.0-3.0",1,INDEX(ModelOutput!$D$16:$D$26,MATCH($C$10,ModelOutput!$C$16:$C$26,0))) -> 0.87654762 | E22: =IF($C$10="2.0-3.0",1,INDEX(ModelOutput!$E$16:$E$26,MATCH($C$10,ModelOutput!$C$16:$C$26,0))) -> 0.87654762 | F22: =IF($C$10="2.0-3.0",1,INDEX(ModelOutput!$F$16:$F$26,MATCH($C$10,ModelOutput!$C$16:$C$26,0))) -> 0.87654762 | G22: =IF($C$10="2.0-3.0",1,INDEX(ModelOutput!$G$16:$G$26,MATCH($C$10,ModelOutput!$C$16:$C$26,0))) -> 0.87654762
B23: Expected loss cost | C23: product of the above | D23: =D17*D18*D19*D20*D21*D22 -> 37.520753 | E23: =E17*E18*E19*E20*E21*E22 -> 110.61296 | F23: =F17*F18*F19*F20*F21*F22 -> 128.32749 | G23: =G17*G18*G19*G20*G21*G22 -> 21.315793 | H23: =SUM(D23:G23) -> 297.777
B24: x Trend / LAE / expense / profit | C24: RateBuildup (Assumptions) | D24: =GROSS_MULT -> 1.626078 | E24: =GROSS_MULT -> 1.626078 | F24: =GROSS_MULT -> 1.626078 | G24: =GROSS_MULT -> 1.626078
B25: Coverage premium | D25: =D23*D24 -> 61.011669 | E25: =E23*E24 -> 179.8653 | F25: =F23*F24 -> 208.67051 | G25: =G23*G24 -> 34.661141 | H25: =SUM(D25:G25) -> 484.20862
B26: + Policy fee | C26: Assumptions | H26: =POLICY_FEE -> 41.666667
B27: TOTAL ANNUAL PREMIUM | H27: =H25+H26 -> 525.87528
B29: COMPARISON TO TODAY
B30: Today's flat premium | H30: =CURRENT_FLAT -> 1426.2298 | I30: Same for every student under the current plan
B31: Change vs today | H31: =H27/CURRENT_FLAT-1 -> -0.63128292 | I31: Positive = this student is underpriced today
B32: Year-1 premium if capped | H32: =MEDIAN(CURRENT_FLAT*(1-CAP_DOWN),H27,CURRENT_FLAT*(1+CAP_UP)) -> 1069.6723
B33: Years to reach indicated | H33: =IF(H27>CURRENT_FLAT,ROUNDUP(LN(H27/CURRENT_FLAT)/LN(1+CAP_UP),0),IF(H27<CURRENT_FLAT,ROUNDUP(LN(H27/CURRENT_FLAT)/LN(1-CAP_DOWN),0),0)) -> 4

Sheet Segments
B1: Segment Engine — all 400 rating cells | AG1: Weighted avg indicated premium | AH1: =SUMPRODUCT($H$5:$H$404,$Z$5:$Z$404)/SUM($H$5:$H$404) -> 1426.2298
B2: Every student belongs to exactly one row. 375 of the 400 combinations occur in the book. Premium here reproduces the Python model exactly — see the check at AG1. | AG2: Total students | AH2: =SUM($H$5:$H$404) -> 10000
AG3: Weighted avg loss cost | AH3: =SUMPRODUCT($H$5:$H$404,$Y$5:$Y$404)/SUM($H$5:$H$404) -> 851.474
A4: Greek | B4: Distance band | C4: Sprinklered | D4: GPA band | E4: Class | F4: Tier | G4: Class adj | H4: Students | I4: F class | J4: F Greek | K4: F sprinkler | L4: F GPA | M4: F dist PP | N4: F dist ALE | O4: F dist GM | P4: F dist LIAB | Q4: Base PP | R4: Base ALE | S4: Base GM | T4: Base LIAB | U4: Loss cost PP | V4: Loss cost ALE | W4: Loss cost GM | X4: Loss cost LIAB | Y4: Loss cost total | Z4: Indicated premium | AA4: Change vs flat | AB4: Capped premium | AC4: Years to indicated | AD4: Model loss cost (Python) | AE4: Check diff | AF4: Years left to graduate | AG4: CHECK: max |Excel - Python| loss cost | AH4: {=SUMPRODUCT(MAX(ABS($AE$5:$AE$404)))} -> 2.8194336e-11
A5: Non-greek | B5: On campus | C5: Yes | D5: <1.0 | E5: Freshman | F5: 1 | G5: Base | H5: 61 | I5: =IF($G5="Base",1,INDEX(ModelOutput!$D$16:$D$26,MATCH($G5,ModelOutput!$C$16:$C$26,0))) -> 1 | J5: =IF($A5="Non-greek",1,INDEX(ModelOutput!$D$16:$D$26,MATCH($A5,ModelOutput!$C$16:$C$26,0))) -> 1 | K5: =IF($C5="Yes",1,INDEX(ModelOutput!$D$16:$D$26,MATCH($C5,ModelOutput!$C$16:$C$26,0))) -> 1 | L5: =IF($D5="2.0-3.0",1,INDEX(ModelOutput!$D$16:$D$26,MATCH($D5,ModelOutput!$C$16:$C$26,0))) -> 1.121448 | M5: =IF($B5="On campus",1,INDEX(ModelOutput!$D$16:$D$26,MATCH($B5,ModelOutput!$C$16:$C$26,0))) -> 1 | N5: =IF($B5="On campus",1,INDEX(ModelOutput!$E$16:$E$26,MATCH($B5,ModelOutput!$C$16:$C$26,0))) -> 1 | O5: =IF($B5="On campus",1,INDEX(ModelOutput!$F$16:$F$26,MATCH($B5,ModelOutput!$C$16:$C$26,0))) -> 1 | P5: =IF($B5="On campus",1,INDEX(ModelOutput!$G$16:$G$26,MATCH($B5,ModelOutput!$C$16:$C$26,0))) -> 1 | Q5: =INDEX(ModelOutput!$D$9:$D$11,MATCH("Tier "&$F5,ModelOutput!$B$9:$B$11,0)) -> 36.175497 | R5: =INDEX(ModelOutput!$E$9:$E$11,MATCH("Tier "&$F5,ModelOutput!$B$9:$B$11,0)) -> 106.64708 | S5: =INDEX(ModelOutput!$F$9:$F$11,MATCH("Tier "&$F5,ModelOutput!$B$9:$B$11,0)) -> 123.72648 | T5: =INDEX(ModelOutput!$G$9:$G$11,MATCH("Tier "&$F5,ModelOutput!$B$9:$B$11,0)) -> 20.551544 | U5: =$Q5*$I5*$J5*$K5*$L5*$M5 -> 40.568939 | V5: =$R5*$I5*$J5*$K5*$L5*$N5 -> 119.59916 | W5: =$S5*$I5*$J5*$K5*$L5*$O5 -> 138.75282 | X5: =$T5*$I5*$J5*$K5*$L5*$P5 -> 23.047488 | Y5: =SUM(U5:X5) -> 321.9684 | Z5: =$Y5*GROSS_MULT+POLICY_FEE -> 565.21239 | AA5: =$Z5/CURRENT_FLAT-1 -> -0.60370173 | AB5: =MEDIAN(CURRENT_FLAT*(1-CAP_DOWN),$Z5,CURRENT_FLAT*(1+CAP_UP)) -> 1069.6723 | AC5: =IF($Z5>CURRENT_FLAT,ROUNDUP(LN($Z5/CURRENT_FLAT)/LN(1+CAP_UP),0),IF($Z5<CURRENT_FLAT,ROUNDUP(LN($Z5/CURRENT_FLAT)/LN(1-CAP_DOWN),0),0)) -> 4 | AD5: 321.9684 | AE5: =$Y5-$AD5 -> -6.2527761e-13 | AF5: =IF($E5="Freshman",4,IF($E5="Sophomore",3,IF($E5="Junior",2,IF($E5="Senior",1,2)))) -> 4
A6: Non-greek | B6: On campus | C6: Yes | D6: <1.0 | E6: Sophomore | F6: 1 | G6: Sophomore | H6: 79 | I6: =IF($G6="Base",1,INDEX(ModelOutput!$D$16:$D$26,MATCH($G6,ModelOutput!$C$16:$C$26,0))) -> 0.98982624 | J6: =IF($A6="Non-greek",1,INDEX(ModelOutput!$D$16:$D$26,MATCH($A6,ModelOutput!$C$16:$C$26,0))) -> 1 | K6: =IF($C6="Yes",1,INDEX(ModelOutput!$D$16:$D$26,MATCH($C6,ModelOutput!$C$16:$C$26,0))) -> 1 | L6: =IF($D6="2.0-3.0",1,INDEX(ModelOutput!$D$16:$D$26,MATCH($D6,ModelOutput!$C$16:$C$26,0))) -> 1.121448 | M6: =IF($B6="On campus",1,INDEX(ModelOutput!$D$16:$D$26,MATCH($B6,ModelOutput!$C$16:$C$26,0))) -> 1 | N6: =IF($B6="On campus",1,INDEX(ModelOutput!$E$16:$E$26,MATCH($B6,ModelOutput!$C$16:$C$26,0))) -> 1 | O6: =IF($B6="On campus",1,INDEX(ModelOutput!$F$16:$F$26,MATCH($B6,ModelOutput!$C$16:$C$26,0))) -> 1 | P6: =IF($B6="On campus",1,INDEX(ModelOutput!$G$16:$G$26,MATCH($B6,ModelOutput!$C$16:$C$26,0))) -> 1 | Q6: =INDEX(ModelOutput!$D$9:$D$11,MATCH("Tier "&$F6,ModelOutput!$B$9:$B$11,0)) -> 36.175497 | R6: =INDEX(ModelOutput!$E$9:$E$11,MATCH("Tier "&$F6,ModelOutput!$B$9:$B$11,0)) -> 106.64708 | S6: =INDEX(ModelOutput!$F$9:$F$11,MATCH("Tier "&$F6,ModelOutput!$B$9:$B$11,0)) -> 123.72648 | T6: =INDEX(ModelOutput!$G$9:$G$11,MATCH("Tier "&$F6,ModelOutput!$B$9:$B$11,0)) -> 20.551544 | U6: =$Q6*$I6*$J6*$K6*$L6*$M6 -> 40.1562 | V6: =$R6*$I6*$J6*$K6*$L6*$N6 -> 118.38239 | W6: =$S6*$I6*$J6*$K6*$L6*$O6 -> 137.34118 | X6: =$T6*$I6*$J6*$K6*$L6*$P6 -> 22.813009 | Y6: =SUM(U6:X6) -> 318.69278 | Z6: =$Y6*GROSS_MULT+POLICY_FEE -> 559.88596 | AA6: =$Z6/CURRENT_FLAT-1 -> -0.60743635 | AB6: =MEDIAN(CURRENT_FLAT*(1-CAP_DOWN),$Z6,CURRENT_FLAT*(1+CAP_UP)) -> 1069.6723 | AC6: =IF($Z6>CURRENT_FLAT,ROUNDUP(LN($Z6/CURRENT_FLAT)/LN(1+CAP_UP),0),IF($Z6<CURRENT_FLAT,ROUNDUP(LN($Z6/CURRENT_FLAT)/LN(1-CAP_DOWN),0),0)) -> 4 | AD6: 318.69278 | AE6: =$Y6-$AD6 -> 0 | AF6: =IF($E6="Freshman",4,IF($E6="Sophomore",3,IF($E6="Junior",2,IF($E6="Senior",1,2)))) -> 3
A7: Non-greek | B7: On campus | C7: Yes | D7: <1.0 | E7: Junior | F7: 2 | G7: Base | H7: 79 | I7: =IF($G7="Base",1,INDEX(ModelOutput!$D$16:$D$26,MATCH($G7,ModelOutput!$C$16:$C$26,0))) -> 1 | J7: =IF($A7="Non-greek",1,INDEX(ModelOutput!$D$16:$D$26,MATCH($A7,ModelOutput!$C$16:$C$26,0))) -> 1 | K7: =IF($C7="Yes",1,INDEX(ModelOutput!$D$16:$D$26,MATCH($C7,ModelOutput!$C$16:$C$26,0))) -> 1 | L7: =IF($D7="2.0-3.0",1,INDEX(ModelOutput!$D$16:$D$26,MATCH($D7,ModelOutput!$C$16:$C$26,0))) -> 1.121448 | M7: =IF($B7="On campus",1,INDEX(ModelOutput!$D$16:$D$26,MATCH($B7,ModelOutput!$C$16:$C$26,0))) -> 1 | N7: =IF($B7="On campus",1,INDEX(ModelOutput!$E$16:$E$26,MATCH($B7,ModelOutput!$C$16:$C$26,0))) -> 1 | O7: =IF($B7="On campus",1,INDEX(ModelOutput!$F$16:$F$26,MATCH($B7,ModelOutput!$C$16:$C$26,0))) -> 1 | P7: =IF($B7="On campus",1,INDEX(ModelOutput!$G$16:$G$26,MATCH($B7,ModelOutput!$C$16:$C$26,0))) -> 1 | Q7: =INDEX(ModelOutput!$D$9:$D$11,MATCH("Tier "&$F7,ModelOutput!$B$9:$B$11,0)) -> 42.805151 | R7: =INDEX(ModelOutput!$E$9:$E$11,MATCH("Tier "&$F7,ModelOutput!$B$9:$B$11,0)) -> 126.19162 | S7: =INDEX(ModelOutput!$F$9:$F$11,MATCH("Tier "&$F7,ModelOutput!$B$9:$B$11,0)) -> 146.40105 | T7: =INDEX(ModelOutput!$G$9:$G$11,MATCH("Tier "&$F7,ModelOutput!$B$9:$B$11,0)) -> 24.317895 | U7: =$Q7*$I7*$J7*$K7*$L7*$M7 -> 48.003751 | V7: =$R7*$I7*$J7*$K7*$L7*$N7 -> 141.51734 | W7: =$S7*$I7*$J7*$K7*$L7*$O7 -> 164.18117 | X7: =$T7*$I7*$J7*$K7*$L7*$P7 -> 27.271255 | Y7: =SUM(U7:X7) -> 380.97351 | Z7: =$Y7*GROSS_MULT+POLICY_FEE -> 661.15929 | AA7: =$Z7/CURRENT_FLAT-1 -> -0.53642863 | AB7: =MEDIAN(CURRENT_FLAT*(1-CAP_DOWN),$Z7,CURRENT_FLAT*(1+CAP_UP)) -> 1069.6723 | AC7: =IF($Z7>CURRENT_FLAT,ROUNDUP(LN($Z7/CURRENT_FLAT)/LN(1+CAP_UP),0),IF($Z7<CURRENT_FLAT,ROUNDUP(LN($Z7/CURRENT_FLAT)/LN(1-CAP_DOWN),0),0)) -> 3 | AD7: 380.97351 | AE7: =$Y7-$AD7 -> 0 | AF7: =IF($E7="Freshman",4,IF($E7="Sophomore",3,IF($E7="Junior",2,IF($E7="Senior",1,2)))) -> 2 | AG7: Years left in school (helper for capping)
A8: Non-greek | B8: On campus | C8: Yes | D8: <1.0 | E8: Senior | F8: 3 | G8: Base | H8: 58 | I8: =IF($G8="Base",1,INDEX(ModelOutput!$D$16:$D$26,MATCH($G8,ModelOutput!$C$16:$C$26,0))) -> 1 | J8: =IF($A8="Non-greek",1,INDEX(ModelOutput!$D$16:$D$26,MATCH($A8,ModelOutput!$C$16:$C$26,0))) -> 1 | K8: =IF($C8="Yes",1,INDEX(ModelOutput!$D$16:$D$26,MATCH($C8,ModelOutput!$C$16:$C$26,0))) -> 1 | L8: =IF($D8="2.0-3.0",1,INDEX(ModelOutput!$D$16:$D$26,MATCH($D8,ModelOutput!$C$16:$C$26,0))) -> 1.121448 | M8: =IF($B8="On campus",1,INDEX(ModelOutput!$D$16:$D$26,MATCH($B8,ModelOutput!$C$16:$C$26,0))) -> 1 | N8: =IF($B8="On campus",1,INDEX(ModelOutput!$E$16:$E$26,MATCH($B8,ModelOutput!$C$16:$C$26,0))) -> 1 | O8: =IF($B8="On campus",1,INDEX(ModelOutput!$F$16:$F$26,MATCH($B8,ModelOutput!$C$16:$C$26,0))) -> 1 | P8: =IF($B8="On campus",1,INDEX(ModelOutput!$G$16:$G$26,MATCH($B8,ModelOutput!$C$16:$C$26,0))) -> 1 | Q8: =INDEX(ModelOutput!$D$9:$D$11,MATCH("Tier "&$F8,ModelOutput!$B$9:$B$11,0)) -> 40.009437 | R8: =INDEX(ModelOutput!$E$9:$E$11,MATCH("Tier "&$F8,ModelOutput!$B$9:$B$11,0)) -> 117.94972 | S8: =INDEX(ModelOutput!$F$9:$F$11,MATCH("Tier "&$F8,ModelOutput!$B$9:$B$11,0)) -> 136.83923 | T8: =INDEX(ModelOutput!$G$9:$G$11,MATCH("Tier "&$F8,ModelOutput!$B$9:$B$11,0)) -> 22.729632 | U8: =$Q8*$I8*$J8*$K8*$L8*$M8 -> 44.868504 | V8: =$R8*$I8*$J8*$K8*$L8*$N8 -> 132.27448 | W8: =$S8*$I8*$J8*$K8*$L8*$O8 -> 153.45808 | X8: =$T8*$I8*$J8*$K8*$L8*$P8 -> 25.4901 | Y8: =SUM(U8:X8) -> 356.09116 | Z8: =$Y8*GROSS_MULT+POLICY_FEE -> 620.69865 | AA8: =$Z8/CURRENT_FLAT-1 -> -0.56479758 | AB8: =MEDIAN(CURRENT_FLAT*(1-CAP_DOWN),$Z8,CURRENT_FLAT*(1+CAP_UP)) -> 1069.6723 | AC8: =IF($Z8>CURRENT_FLAT,ROUNDUP(LN($Z8/CURRENT_FLAT)/LN(1+CAP_UP),0),IF($Z8<CURRENT_FLAT,ROUNDUP(LN($Z8/CURRENT_FLAT)/LN(1-CAP_DOWN),0),0)) -> 3 | AD8: 356.09116 | AE8: =$Y8-$AD8 -> -1.080025e-12 | AF8: =IF($E8="Freshman",4,IF($E8="Sophomore",3,IF($E8="Junior",2,IF($E8="Senior",1,2)))) -> 1
A9: Non-greek | B9: On campus | C9: Yes | D9: <1.0 | E9: Grad student | F9: 3 | G9: Grad | H9: 48 | I9: =IF($G9="Base",1,INDEX(ModelOutput!$D$16:$D$26,MATCH($G9,ModelOutput!$C$16:$C$26,0))) -> 1.1906804 | J9: =IF($A9="Non-greek",1,INDEX(ModelOutput!$D$16:$D$26,MATCH($A9,ModelOutput!$C$16:$C$26,0))) -> 1 | K9: =IF($C9="Yes",1,INDEX(ModelOutput!$D$16:$D$26,MATCH($C9,ModelOutput!$C$16:$C$26,0))) -> 1 | L9: =IF($D9="2.0-3.0",1,INDEX(ModelOutput!$D$16:$D$26,MATCH($D9,ModelOutput!$C$16:$C$26,0))) -> 1.121448 | M9: =IF($B9="On campus",1,INDEX(ModelOutput!$D$16:$D$26,MATCH($B9,ModelOutput!$C$16:$C$26,0))) -> 1 | N9: =IF($B9="On campus",1,INDEX(ModelOutput!$E$16:$E$26,MATCH($B9,ModelOutput!$C$16:$C$26,0))) -> 1 | O9: =IF($B9="On campus",1,INDEX(ModelOutput!$F$16:$F$26,MATCH($B9,ModelOutput!$C$16:$C$26,0))) -> 1 | P9: =IF($B9="On campus",1,INDEX(ModelOutput!$G$16:$G$26,MATCH($B9,ModelOutput!$C$16:$C$26,0))) -> 1 | Q9: =INDEX(ModelOutput!$D$9:$D$11,MATCH("Tier "&$F9,ModelOutput!$B$9:$B$11,0)) -> 40.009437 | R9: =INDEX(ModelOutput!$E$9:$E$11,MATCH("Tier "&$F9,ModelOutput!$B$9:$B$11,0)) -> 117.94972 | S9: =INDEX(ModelOutput!$F$9:$F$11,MATCH("Tier "&$F9,ModelOutput!$B$9:$B$11,0)) -> 136.83923 | T9: =INDEX(ModelOutput!$G$9:$G$11,MATCH("Tier "&$F9,ModelOutput!$B$9:$B$11,0)) -> 22.729632 | U9: =$Q9*$I9*$J9*$K9*$L9*$M9 -> 53.424049 | V9: =$R9*$I9*$J9*$K9*$L9*$N9 -> 157.49664 | W9: =$S9*$I9*$J9*$K9*$L9*$O9 -> 182.71953 | X9: =$T9*$I9*$J9*$K9*$L9*$P9 -> 30.350563 | Y9: =SUM(U9:X9) -> 423.99078 | Z9: =$Y9*GROSS_MULT+POLICY_FEE -> 731.10872 | AA9: =$Z9/CURRENT_FLAT-1 -> -0.48738364 | AB9: =MEDIAN(CURRENT_FLAT*(1-CAP_DOWN),$Z9,CURRENT_FLAT*(1+CAP_UP)) -> 1069.6723 | AC9: =IF($Z9>CURRENT_FLAT,ROUNDUP(LN($Z9/CURRENT_FLAT)/LN(1+CAP_UP),0),IF($Z9<CURRENT_FLAT,ROUNDUP(LN($Z9/CURRENT_FLAT)/LN(1-CAP_DOWN),0),0)) -> 3 | AD9: 423.99078 | AE9: =$Y9-$AD9 -> -1.7053026e-12 | AF9: =IF($E9="Freshman",4,IF($E9="Sophomore",3,IF($E9="Junior",2,IF($E9="Senior",1,2)))) -> 2
A10: Non-greek | B10: On campus | C10: Yes | D10: 1.0-2.0 | E10: Freshman | F10: 1 | G10: Base | H10: 188 | I10: =IF($G10="Base",1,INDEX(ModelOutput!$D$16:$D$26,MATCH($G10,ModelOutput!$C$16:$C$26,0))) -> 1 | J10: =IF($A10="Non-greek",1,INDEX(ModelOutput!$D$16:$D$26,MATCH($A10,ModelOutput!$C$16:$C$26,0))) -> 1 | K10: =IF($C10="Yes",1,INDEX(ModelOutput!$D$16:$D$26,MATCH($C10,ModelOutput!$C$16:$C$26,0))) -> 1 | L10: =IF($D10="2.0-3.0",1,INDEX(ModelOutput!$D$16:$D$26,MATCH($D10,ModelOutput!$C$16:$C$26,0))) -> 1.0176256 | M10: =IF($B10="On campus",1,INDEX(ModelOutput!$D$16:$D$26,MATCH($B10,ModelOutput!$C$16:$C$26,0))) -> 1 | N10: =IF($B10="On campus",1,INDEX(ModelOutput!$E$16:$E$26,MATCH($B10,ModelOutput!$C$16:$C$26,0))) -> 1 | O10: =IF($B10="On campus",1,INDEX(ModelOutput!$F$16:$F$26,MATCH($B10,ModelOutput!$C$16:$C$26,0))) -> 1 | P10: =IF($B10="On campus",1,INDEX(ModelOutput!$G$16:$G$26,MATCH($B10,ModelOutput!$C$16:$C$26,0))) -> 1 | Q10: =INDEX(ModelOutput!$D$9:$D$11,MATCH("Tier "&$F10,ModelOutput!$B$9:$B$11,0)) -> 36.175497 | R10: =INDEX(ModelOutput!$E$9:$E$11,MATCH("Tier "&$F10,ModelOutput!$B$9:$B$11,0)) -> 106.64708 | S10: =INDEX(ModelOutput!$F$9:$F$11,MATCH("Tier "&$F10,ModelOutput!$B$9:$B$11,0)) -> 123.72648 | T10: =INDEX(ModelOutput!$G$9:$G$11,MATCH("Tier "&$F10,ModelOutput!$B$9:$B$11,0)) -> 20.551544 | U10: =$Q10*$I10*$J10*$K10*$L10*$M10 -> 36.81311 | V10: =$R10*$I10*$J10*$K10*$L10*$N10 -> 108.5268 | W10: =$S10*$I10*$J10*$K10*$L10*$O10 -> 125.90723 | X10: =$T10*$I10*$J10*$K10*$L10*$P10 -> 20.913777 | Y10: =SUM(U10:X10) -> 292.16092 | Z10: =$Y10*GROSS_MULT+POLICY_FEE -> 516.7431 | AA10: =$Z10/CURRENT_FLAT-1 -> -0.63768594 | AB10: =MEDIAN(CURRENT_FLAT*(1-CAP_DOWN),$Z10,CURRENT_FLAT*(1+CAP_UP)) -> 1069.6723 | AC10: =IF($Z10>CURRENT_FLAT,ROUNDUP(LN($Z10/CURRENT_FLAT)/LN(1+CAP_UP),0),IF($Z10<CURRENT_FLAT,ROUNDUP(LN($Z10/CURRENT_FLAT)/LN(1-CAP_DOWN),0),0)) -> 4 | AD10: 292.16092 | AE10: =$Y10-$AD10 -> 4.5474735e-13 | AF10: =IF($E10="Freshman",4,IF($E10="Sophomore",3,IF($E10="Junior",2,IF($E10="Senior",1,2)))) -> 4
A11: Non-greek | B11: On campus | C11: Yes | D11: 1.0-2.0 | E11: Sophomore | F11: 1 | G11: Sophomore | H11: 216 | I11: =IF($G11="Base",1,INDEX(ModelOutput!$D$16:$D$26,MATCH($G11,ModelOutput!$C$16:$C$26,0))) -> 0.98982624 | J11: =IF($A11="Non-greek",1,INDEX(ModelOutput!$D$16:$D$26,MATCH($A11,ModelOutput!$C$16:$C$26,0))) -> 1 | K11: =IF($C11="Yes",1,INDEX(ModelOutput!$D$16:$D$26,MATCH($C11,ModelOutput!$C$16:$C$26,0))) -> 1 | L11: =IF($D11="2.0-3.0",1,INDEX(ModelOutput!$D$16:$D$26,MATCH($D11,ModelOutput!$C$16:$C$26,0))) -> 1.0176256 | M11: =IF($B11="On campus",1,INDEX(ModelOutput!$D$16:$D$26,MATCH($B11,ModelOutput!$C$16:$C$26,0))) -> 1 | N11: =IF($B11="On campus",1,INDEX(ModelOutput!$E$16:$E$26,MATCH($B11,ModelOutput!$C$16:$C$26,0))) -> 1 | O11: =IF($B11="On campus",1,INDEX(ModelOutput!$F$16:$F$26,MATCH($B11,ModelOutput!$C$16:$C$26,0))) -> 1 | P11: =IF($B11="On campus",1,INDEX(ModelOutput!$G$16:$G$26,MATCH($B11,ModelOutput!$C$16:$C$26,0))) -> 1 | Q11: =INDEX(ModelOutput!$D$9:$D$11,MATCH("Tier "&$F11,ModelOutput!$B$9:$B$11,0)) -> 36.175497 | R11: =INDEX(ModelOutput!$E$9:$E$11,MATCH("Tier "&$F11,ModelOutput!$B$9:$B$11,0)) -> 106.64708 | S11: =INDEX(ModelOutput!$F$9:$F$11,MATCH("Tier "&$F11,ModelOutput!$B$9:$B$11,0)) -> 123.72648 | T11: =INDEX(ModelOutput!$G$9:$G$11,MATCH("Tier "&$F11,ModelOutput!$B$9:$B$11,0)) -> 20.551544 | U11: =$Q11*$I11*$J11*$K11*$L11*$M11 -> 36.438583 | V11: =$R11*$I11*$J11*$K11*$L11*$N11 -> 107.42267 | W11: =$S11*$I11*$J11*$K11*$L11*$O11 -> 124.62628 | X11: =$T11*$I11*$J11*$K11*$L11*$P11 -> 20.701005 | Y11: =SUM(U11:X11) -> 289.18854 | Z11: =$Y11*GROSS_MULT+POLICY_FEE -> 511.90978 | AA11: =$Z11/CURRENT_FLAT-1 -> -0.64107482 | AB11: =MEDIAN(CURRENT_FLAT*(1-CAP_DOWN),$Z11,CURRENT_FLAT*(1+CAP_UP)) -> 1069.6723 | AC11: =IF($Z11>CURRENT_FLAT,ROUNDUP(LN($Z11/CURRENT_FLAT)/LN(1+CAP_UP),0),IF($Z11<CURRENT_FLAT,ROUNDUP(LN($Z11/CURRENT_FLAT)/LN(1-CAP_DOWN),0),0)) -> 4 | AD11: 289.18854 | AE11: =$Y11-$AD11 -> 0 | AF11: =IF($E11="Freshman",4,IF($E11="Sophomore",3,IF($E11="Junior",2,IF($E11="Senior",1,2)))) -> 3
A12: Non-greek | B12: On campus | C12: Yes | D12: 1.0-2.0 | E12: Junior | F12: 2 | G12: Base | H12: 194 | I12: =IF($G12="Base",1,INDEX(ModelOutput!$D$16:$D$26,MATCH($G12,ModelOutput!$C$16:$C$26,0))) -> 1 | J12: =IF($A12="Non-greek",1,INDEX(ModelOutput!$D$16:$D$26,MATCH($A12,ModelOutput!$C$16:$C$26,0))) -> 1 | K12: =IF($C12="Yes",1,INDEX(ModelOutput!$D$16:$D$26,MATCH($C12,ModelOutput!$C$16:$C$26,0))) -> 1 | L12: =IF($D12="2.0-3.0",1,INDEX(ModelOutput!$D$16:$D$26,MATCH($D12,ModelOutput!$C$16:$C$26,0))) -> 1.0176256 | M12: =IF($B12="On campus",1,INDEX(ModelOutput!$D$16:$D$26,MATCH($B12,ModelOutput!$C$16:$C$26,0))) -> 1 | N12: =IF($B12="On campus",1,INDEX(ModelOutput!$E$16:$E$26,MATCH($B12,ModelOutput!$C$16:$C$26,0))) -> 1 | O12: =IF($B12="On campus",1,INDEX(ModelOutput!$F$16:$F$26,MATCH($B12,ModelOutput!$C$16:$C$26,0))) -> 1 | P12: =IF($B12="On campus",1,INDEX(ModelOutput!$G$16:$G$26,MATCH($B12,ModelOutput!$C$16:$C$26,0))) -> 1 | Q12: =INDEX(ModelOutput!$D$9:$D$11,MATCH("Tier "&$F12,ModelOutput!$B$9:$B$11,0)) -> 42.805151 | R12: =INDEX(ModelOutput!$E$9:$E$11,MATCH("Tier "&$F12,ModelOutput!$B$9:$B$11,0)) -> 126.19162 | S12: =INDEX(ModelOutput!$F$9:$F$11,MATCH("Tier "&$F12,ModelOutput!$B$9:$B$11,0)) -> 146.40105 | T12: =INDEX(ModelOutput!$G$9:$G$11,MATCH("Tier "&$F12,ModelOutput!$B$9:$B$11,0)) -> 24.317895 | U12: =$Q12*$I12*$J12*$K12*$L12*$M12 -> 43.559615 | V12: =$R12*$I12*$J12*$K12*$L12*$N12 -> 128.41582 | W12: =$S12*$I12*$J12*$K12*$L12*$O12 -> 148.98145 | X12: =$T12*$I12*$J12*$K12*$L12*$P12 -> 24.746512 | Y12: =SUM(U12:X12) -> 345.70339 | Z12: =$Y12*GROSS_MULT+POLICY_FEE -> 603.80734 | AA12: =$Z12/CURRENT_FLAT-1 -> -0.57664091 | AB12: =MEDIAN(CURRENT_FLAT*(1-CAP_DOWN),$Z12,CURRENT_FLAT*(1+CAP_UP)) -> 1069.6723 | AC12: =IF($Z12>CURRENT_FLAT,ROUNDUP(LN($Z12/CURRENT_FLAT)/LN(1+CAP_UP),0),IF($Z12<CURRENT_FLAT,ROUNDUP(LN($Z12/CURRENT_FLAT)/LN(1-CAP_DOWN),0),0)) -> 3 | AD12: 345.70339 | AE12: =$Y12-$AD12 -> -5.6843419e-13 | AF12: =IF($E12="Freshman",4,IF($E12="Sophomore",3,IF($E12="Junior",2,IF($E12="Senior",1,2)))) -> 2
A13: Non-greek | B13: On campus | C13: Yes | D13: 1.0-2.0 | E13: Senior | F13: 3 | G13: Base | H13: 209 | I13: =IF($G13="Base",1,INDEX(ModelOutput!$D$16:$D$26,MATCH($G13,ModelOutput!$C$16:$C$26,0))) -> 1 | J13: =IF($A13="Non-greek",1,INDEX(ModelOutput!$D$16:$D$26,MATCH($A13,ModelOutput!$C$16:$C$26,0))) -> 1 | K13: =IF($C13="Yes",1,INDEX(ModelOutput!$D$16:$D$26,MATCH($C13,ModelOutput!$C$16:$C$26,0))) -> 1 | L13: =IF($D13="2.0-3.0",1,INDEX(ModelOutput!$D$16:$D$26,MATCH($D13,ModelOutput!$C$16:$C$26,0))) -> 1.0176256 | M13: =IF($B13="On campus",1,INDEX(ModelOutput!$D$16:$D$26,MATCH($B13,ModelOutput!$C$16:$C$26,0))) -> 1 | N13: =IF($B13="On campus",1,INDEX(ModelOutput!$E$16:$E$26,MATCH($B13,ModelOutput!$C$16:$C$26,0))) -> 1 | O13: =IF($B13="On campus",1,INDEX(ModelOutput!$F$16:$F$26,MATCH($B13,ModelOutput!$C$16:$C$26,0))) -> 1 | P13: =IF($B13="On campus",1,INDEX(ModelOutput!$G$16:$G$26,MATCH($B13,ModelOutput!$C$16:$C$26,0))) -> 1 | Q13: =INDEX(ModelOutput!$D$9:$D$11,MATCH("Tier "&$F13,ModelOutput!$B$9:$B$11,0)) -> 40.009437 | R13: =INDEX(ModelOutput!$E$9:$E$11,MATCH("Tier "&$F13,ModelOutput!$B$9:$B$11,0)) -> 117.94972 | S13: =INDEX(ModelOutput!$F$9:$F$11,MATCH("Tier "&$F13,ModelOutput!$B$9:$B$11,0)) -> 136.83923 | T13: =INDEX(ModelOutput!$G$9:$G$11,MATCH("Tier "&$F13,ModelOutput!$B$9:$B$11,0)) -> 22.729632 | U13: =$Q13*$I13*$J13*$K13*$L13*$M13 -> 40.714626 | V13: =$R13*$I13*$J13*$K13*$L13*$N13 -> 120.02865 | W13: =$S13*$I13*$J13*$K13*$L13*$O13 -> 139.25109 | X13: =$T13*$I13*$J13*$K13*$L13*$P13 -> 23.130254 | Y13: =SUM(U13:X13) -> 323.12463 | Z13: =$Y13*GROSS_MULT+POLICY_FEE -> 567.0925 | AA13: =$Z13/CURRENT_FLAT-1 -> -0.60238349 | AB13: =MEDIAN(CURRENT_FLAT*(1-CAP_DOWN),$Z13,CURRENT_FLAT*(1+CAP_UP)) -> 1069.6723 | AC13: =IF($Z13>CURRENT_FLAT,ROUNDUP(LN($Z13/CURRENT_FLAT)/LN(1+CAP_UP),0),IF($Z13<CURRENT_FLAT,ROUNDUP(LN($Z13/CURRENT_FLAT)/LN(1-CAP_DOWN),0),0)) -> 4 | AD13: 323.12463 | AE13: =$Y13-$AD13 -> -1.1368684e-12 | AF13: =IF($E13="Freshman",4,IF($E13="Sophomore",3,IF($E13="Junior",2,IF($E13="Senior",1,2)))) -> 1
A14: Non-greek | B14: On campus | C14: Yes | D14: 1.0-2.0 | E14: Grad student | F14: 3 | G14: Grad | H14: 113 | I14: =IF($G14="Base",1,INDEX(ModelOutput!$D$16:$D$26,MATCH($G14,ModelOutput!$C$16:$C$26,0))) -> 1.1906804 | J14: =IF($A14="Non-greek",1,INDEX(ModelOutput!$D$16:$D$26,MATCH($A14,ModelOutput!$C$16:$C$26,0))) -> 1 | K14: =IF($C14="Yes",1,INDEX(ModelOutput!$D$16:$D$26,MATCH($C14,ModelOutput!$C$16:$C$26,0))) -> 1 | L14: =IF($D14="2.0-3.0",1,INDEX(ModelOutput!$D$16:$D$26,MATCH($D14,ModelOutput!$C$16:$C$26,0))) -> 1.0176256 | M14: =IF($B14="On campus",1,INDEX(ModelOutput!$D$16:$D$26,MATCH($B14,ModelOutput!$C$16:$C$26,0))) -> 1 | N14: =IF($B14="On campus",1,INDEX(ModelOutput!$E$16:$E$26,MATCH($B14,ModelOutput!$C$16:$C$26,0))) -> 1 | O14: =IF($B14="On campus",1,INDEX(ModelOutput!$F$16:$F$26,MATCH($B14,ModelOutput!$C$16:$C$26,0))) -> 1 | P14: =IF($B14="On campus",1,INDEX(ModelOutput!$G$16:$G$26,MATCH($B14,ModelOutput!$C$16:$C$26,0))) -> 1 | Q14: =INDEX(ModelOutput!$D$9:$D$11,MATCH("Tier "&$F14,ModelOutput!$B$9:$B$11,0)) -> 40.009437 | R14: =INDEX(ModelOutput!$E$9:$E$11,MATCH("Tier "&$F14,ModelOutput!$B$9:$B$11,0)) -> 117.94972 | S14: =INDEX(ModelOutput!$F$9:$F$11,MATCH("Tier "&$F14,ModelOutput!$B$9:$B$11,0)) -> 136.83923 | T14: =INDEX(ModelOutput!$G$9:$G$11,MATCH("Tier "&$F14,ModelOutput!$B$9:$B$11,0)) -> 22.729632 | U14: =$Q14*$I14*$J14*$K14*$L14*$M14 -> 48.478108 | V14: =$R14*$I14*$J14*$K14*$L14*$N14 -> 142.91577 | W14: =$S14*$I14*$J14*$K14*$L14*$O14 -> 165.80355 | X14: =$T14*$I14*$J14*$K14*$L14*$P14 -> 27.540741 | Y14: =SUM(U14:X14) -> 384.73817 | Z14: =$Y14*GROSS_MULT+POLICY_FEE -> 667.28092 | AA14: =$Z14/CURRENT_FLAT-1 -> -0.53213645 | AB14: =MEDIAN(CURRENT_FLAT*(1-CAP_DOWN),$Z14,CURRENT_FLAT*(1+CAP_UP)) -> 1069.6723 | AC14: =IF($Z14>CURRENT_FLAT,ROUNDUP(LN($Z14/CURRENT_FLAT)/LN(1+CAP_UP),0),IF($Z14<CURRENT_FLAT,ROUNDUP(LN($Z14/CURRENT_FLAT)/LN(1-CAP_DOWN),0),0)) -> 3 | AD14: 384.73817 | AE14: =$Y14-$AD14 -> -7.3896445e-13 | AF14: =IF($E14="Freshman",4,IF($E14="Sophomore",3,IF($E14="Junior",2,IF($E14="Senior",1,2)))) -> 2
A15: Non-greek | B15: On campus | C15: Yes | D15: 2.0-3.0 | E15: Freshman | F15: 1 | G15: Base | H15: 348 | I15: =IF($G15="Base",1,INDEX(ModelOutput!$D$16:$D$26,MATCH($G15,ModelOutput!$C$16:$C$26,0))) -> 1 | J15: =IF($A15="Non-greek",1,INDEX(ModelOutput!$D$16:$D$26,MATCH($A15,ModelOutput!$C$16:$C$26,0))) -> 1 | K15: =IF($C15="Yes",1,INDEX(ModelOutput!$D$16:$D$26,MATCH($C15,ModelOutput!$C$16:$C$26,0))) -> 1 | L15: =IF($D15="2.0-3.0",1,INDEX(ModelOutput!$D$16:$D$26,MATCH($D15,ModelOutput!$C$16:$C$26,0))) -> 1 | M15: =IF($B15="On campus",1,INDEX(ModelOutput!$D$16:$D$26,MATCH($B15,ModelOutput!$C$16:$C$26,0))) -> 1 | N15: =IF($B15="On campus",1,INDEX(ModelOutput!$E$16:$E$26,MATCH($B15,ModelOutput!$C$16:$C$26,0))) -> 1 | O15: =IF($B15="On campus",1,INDEX(ModelOutput!$F$16:$F$26,MATCH($B15,ModelOutput!$C$16:$C$26,0))) -> 1 | P15: =IF($B15="On campus",1,INDEX(ModelOutput!$G$16:$G$26,MATCH($B15,ModelOutput!$C$16:$C$26,0))) -> 1 | Q15: =INDEX(ModelOutput!$D$9:$D$11,MATCH("Tier "&$F15,ModelOutput!$B$9:$B$11,0)) -> 36.175497 | R15: =INDEX(ModelOutput!$E$9:$E$11,MATCH("Tier "&$F15,ModelOutput!$B$9:$B$11,0)) -> 106.64708 | S15: =INDEX(ModelOutput!$F$9:$F$11,MATCH("Tier "&$F15,ModelOutput!$B$9:$B$11,0)) -> 123.72648 | T15: =INDEX(ModelOutput!$G$9:$G$11,MATCH("Tier "&$F15,ModelOutput!$B$9:$B$11,0)) -> 20.551544 | U15: =$Q15*$I15*$J15*$K15*$L15*$M15 -> 36.175497 | V15: =$R15*$I15*$J15*$K15*$L15*$N15 -> 106.64708 | W15: =$S15*$I15*$J15*$K15*$L15*$O15 -> 123.72648 | X15: =$T15*$I15*$J15*$K15*$L15*$P15 -> 20.551544 | Y15: =SUM(U15:X15) -> 287.10061 | Z15: =$Y15*GROSS_MULT+POLICY_FEE -> 508.51464 | AA15: =$Z15/CURRENT_FLAT-1 -> -0.64345532 | AB15: =MEDIAN(CURRENT_FLAT*(1-CAP_DOWN),$Z15,CURRENT_FLAT*(1+CAP_UP)) -> 1069.6723 | AC15: =IF($Z15>CURRENT_FLAT,ROUNDUP(LN($Z15/CURRENT_FLAT)/LN(1+CAP_UP),0),IF($Z15<CURRENT_FLAT,ROUNDUP(LN($Z15/CURRENT_FLAT)/LN(1-CAP_DOWN),0),0)) -> 4 | AD15: 287.10061 | AE15: =$Y15-$AD15 -> 7.9580786e-13 | AF15: =IF($E15="Freshman",4,IF($E15="Sophomore",3,IF($E15="Junior",2,IF($E15="Senior",1,2)))) -> 4
A16: Non-greek | B16: On campus | C16: Yes | D16: 2.0-3.0 | E16: Sophomore | F16: 1 | G16: Sophomore | H16: 328 | I16: =IF($G16="Base",1,INDEX(ModelOutput!$D$16:$D$26,MATCH($G16,ModelOutput!$C$16:$C$26,0))) -> 0.98982624 | J16: =IF($A16="Non-greek",1,INDEX(ModelOutput!$D$16:$D$26,MATCH($A16,ModelOutput!$C$16:$C$26,0))) -> 1 | K16: =IF($C16="Yes",1,INDEX(ModelOutput!$D$16:$D$26,MATCH($C16,ModelOutput!$C$16:$C$26,0))) -> 1 | L16: =IF($D16="2.0-3.0",1,INDEX(ModelOutput!$D$16:$D$26,MATCH($D16,ModelOutput!$C$16:$C$26,0))) -> 1 | M16: =IF($B16="On campus",1,INDEX(ModelOutput!$D$16:$D$26,MATCH($B16,ModelOutput!$C$16:$C$26,0))) -> 1 | N16: =IF($B16="On campus",1,INDEX(ModelOutput!$E$16:$E$26,MATCH($B16,ModelOutput!$C$16:$C$26,0))) -> 1 | O16: =IF($B16="On campus",1,INDEX(ModelOutput!$F$16:$F$26,MATCH($B16,ModelOutput!$C$16:$C$26,0))) -> 1 | P16: =IF($B16="On campus",1,INDEX(ModelOutput!$G$16:$G$26,MATCH($B16,ModelOutput!$C$16:$C$26,0))) -> 1 | Q16: =INDEX(ModelOutput!$D$9:$D$11,MATCH("Tier "&$F16,ModelOutput!$B$9:$B$11,0)) -> 36.175497 | R16: =INDEX(ModelOutput!$E$9:$E$11,MATCH("Tier "&$F16,ModelOutput!$B$9:$B$11,0)) -> 106.64708 | S16: =INDEX(ModelOutput!$F$9:$F$11,MATCH("Tier "&$F16,ModelOutput!$B$9:$B$11,0)) -> 123.72648 | T16: =INDEX(ModelOutput!$G$9:$G$11,MATCH("Tier "&$F16,ModelOutput!$B$9:$B$11,0)) -> 20.551544 | U16: =$Q16*$I16*$J16*$K16*$L16*$M16 -> 35.807456 | V16: =$R16*$I16*$J16*$K16*$L16*$N16 -> 105.56208 | W16: =$S16*$I16*$J16*$K16*$L16*$O16 -> 122.46772 | X16: =$T16*$I16*$J16*$K16*$L16*$P16 -> 20.342458 | Y16: =SUM(U16:X16) -> 284.17972 | Z16: =$Y16*GROSS_MULT+POLICY_FEE -> 503.76504 | AA16: =$Z16/CURRENT_FLAT-1 -> -0.6467855 | AB16: =MEDIAN(CURRENT_FLAT*(1-CAP_DOWN),$Z16,CURRENT_FLAT*(1+CAP_UP)) -> 1069.6723 | AC16: =IF($Z16>CURRENT_FLAT,ROUNDUP(LN($Z16/CURRENT_FLAT)/LN(1+CAP_UP),0),IF($Z16<CURRENT_FLAT,ROUNDUP(LN($Z16/CURRENT_FLAT)/LN(1-CAP_DOWN),0),0)) -> 4 | AD16: 284.17972 | AE16: =$Y16-$AD16 -> 7.3896445e-13 | AF16: =IF($E16="Freshman",4,IF($E16="Sophomore",3,IF($E16="Junior",2,IF($E16="Senior",1,2)))) -> 3
A17: Non-greek | B17: On campus | C17: Yes | D17: 2.0-3.0 | E17: Junior | F17: 2 | G17: Base | H17: 358 | I17: =IF($G17="Base",1,INDEX(ModelOutput!$D$16:$D$26,MATCH($G17,ModelOutput!$C$16:$C$26,0))) -> 1 | J17: =IF($A17="Non-greek",1,INDEX(ModelOutput!$D$16:$D$26,MATCH($A17,ModelOutput!$C$16:$C$26,0))) -> 1 | K17: =IF($C17="Yes",1,INDEX(ModelOutput!$D$16:$D$26,MATCH($C17,ModelOutput!$C$16:$C$26,0))) -> 1 | L17: =IF($D17="2.0-3.0",1,INDEX(ModelOutput!$D$16:$D$26,MATCH($D17,ModelOutput!$C$16:$C$26,0))) -> 1 | M17: =IF($B17="On campus",1,INDEX(ModelOutput!$D$16:$D$26,MATCH($B17,ModelOutput!$C$16:$C$26,0))) -> 1 | N17: =IF($B17="On campus",1,INDEX(ModelOutput!$E$16:$E$26,MATCH($B17,ModelOutput!$C$16:$C$26,0))) -> 1 | O17: =IF($B17="On campus",1,INDEX(ModelOutput!$F$16:$F$26,MATCH($B17,ModelOutput!$C$16:$C$26,0))) -> 1 | P17: =IF($B17="On campus",1,INDEX(ModelOutput!$G$16:$G$26,MATCH($B17,ModelOutput!$C$16:$C$26,0))) -> 1 | Q17: =INDEX(ModelOutput!$D$9:$D$11,MATCH("Tier "&$F17,ModelOutput!$B$9:$B$11,0)) -> 42.805151 | R17: =INDEX(ModelOutput!$E$9:$E$11,MATCH("Tier "&$F17,ModelOutput!$B$9:$B$11,0)) -> 126.19162 | S17: =INDEX(ModelOutput!$F$9:$F$11,MATCH("Tier "&$F17,ModelOutput!$B$9:$B$11,0)) -> 146.40105 | T17: =INDEX(ModelOutput!$G$9:$G$11,MATCH("Tier "&$F17,ModelOutput!$B$9:$B$11,0)) -> 24.317895 | U17: =$Q17*$I17*$J17*$K17*$L17*$M17 -> 42.805151 | V17: =$R17*$I17*$J17*$K17*$L17*$N17 -> 126.19162 | W17: =$S17*$I17*$J17*$K17*$L17*$O17 -> 146.40105 | X17: =$T17*$I17*$J17*$K17*$L17*$P17 -> 24.317895 | Y17: =SUM(U17:X17) -> 339.71571 | Z17: =$Y17*GROSS_MULT+POLICY_FEE -> 594.0709 | AA17: =$Z17/CURRENT_FLAT-1 -> -0.58346761 | AB17: =MEDIAN(CURRENT_FLAT*(1-CAP_DOWN),$Z17,CURRENT_FLAT*(1+CAP_UP)) -> 1069.6723 | AC17: =IF($Z17>CURRENT_FLAT,ROUNDUP(LN($Z17/CURRENT_FLAT)/LN(1+CAP_UP),0),IF($Z17<CURRENT_FLAT,ROUNDUP(LN($Z17/CURRENT_FLAT)/LN(1-CAP_DOWN),0),0)) -> 4 | AD17: 339.71571 | AE17: =$Y17-$AD17 -> 0 | AF17: =IF($E17="Freshman",4,IF($E17="Sophomore",3,IF($E17="Junior",2,IF($E17="Senior",1,2)))) -> 2
A18: Non-greek | B18: On campus | C18: Yes | D18: 2.0-3.0 | E18: Senior | F18: 3 | G18: Base | H18: 343 | I18: =IF($G18="Base",1,INDEX(ModelOutput!$D$16:$D$26,MATCH($G18,ModelOutput!$C$16:$C$26,0))) -> 1 | J18: =IF($A18="Non-greek",1,INDEX(ModelOutput!$D$16:$D$26,MATCH($A18,ModelOutput!$C$16:$C$26,0))) -> 1 | K18: =IF($C18="Yes",1,INDEX(ModelOutput!$D$16:$D$26,MATCH($C18,ModelOutput!$C$16:$C$26,0))) -> 1 | L18: =IF($D18="2.0-3.0",1,INDEX(ModelOutput!$D$16:$D$26,MATCH($D18,ModelOutput!$C$16:$C$26,0))) -> 1 | M18: =IF($B18="On campus",1,INDEX(ModelOutput!$D$16:$D$26,MATCH($B18,ModelOutput!$C$16:$C$26,0))) -> 1 | N18: =IF($B18="On campus",1,INDEX(ModelOutput!$E$16:$E$26,MATCH($B18,ModelOutput!$C$16:$C$26,0))) -> 1 | O18: =IF($B18="On campus",1,INDEX(ModelOutput!$F$16:$F$26,MATCH($B18,ModelOutput!$C$16:$C$26,0))) -> 1 | P18: =IF($B18="On campus",1,INDEX(ModelOutput!$G$16:$G$26,MATCH($B18,ModelOutput!$C$16:$C$26,0))) -> 1 | Q18: =INDEX(ModelOutput!$D$9:$D$11,MATCH("Tier "&$F18,ModelOutput!$B$9:$B$11,0)) -> 40.009437 | R18: =INDEX(ModelOutput!$E$9:$E$11,MATCH("Tier "&$F18,ModelOutput!$B$9:$B$11,0)) -> 117.94972 | S18: =INDEX(ModelOutput!$F$9:$F$11,MATCH("Tier "&$F18,ModelOutput!$B$9:$B$11,0)) -> 136.83923 | T18: =INDEX(ModelOutput!$G$9:$G$11,MATCH("Tier "&$F18,ModelOutput!$B$9:$B$11,0)) -> 22.729632 | U18: =$Q18*$I18*$J18*$K18*$L18*$M18 -> 40.009437 | V18: =$R18*$I18*$J18*$K18*$L18*$N18 -> 117.94972 | W18: =$S18*$I18*$J18*$K18*$L18*$O18 -> 136.83923 | X18: =$T18*$I18*$J18*$K18*$L18*$P18 -> 22.729632 | Y18: =SUM(U18:X18) -> 317.52802 | Z18: =$Y18*GROSS_MULT+POLICY_FEE -> 557.99198 | AA18: =$Z18/CURRENT_FLAT-1 -> -0.60876432 | AB18: =MEDIAN(CURRENT_FLAT*(1-CAP_DOWN),$Z18,CURRENT_FLAT*(1+CAP_UP)) -> 1069.6723 | AC18: =IF($Z18>CURRENT_FLAT,ROUNDUP(LN($Z18/CURRENT_FLAT)/LN(1+CAP_UP),0),IF($Z18<CURRENT_FLAT,ROUNDUP(LN($Z18/CURRENT_FLAT)/LN(1-CAP_DOWN),0),0)) -> 4 | AD18: 317.52802 | AE18: =$Y18-$AD18 -> -1.0231815e-12 | AF18: =IF($E18="Freshman",4,IF($E18="Sophomore",3,IF($E18="Junior",2,IF($E18="Senior",1,2)))) -> 1
A19: Non-greek | B19: On campus | C19: Yes | D19: 2.0-3.0 | E19: Grad student | F19: 3 | G19: Grad | H19: 146 | I19: =IF($G19="Base",1,INDEX(ModelOutput!$D$16:$D$26,MATCH($G19,ModelOutput!$C$16:$C$26,0))) -> 1.1906804 | J19: =IF($A19="Non-greek",1,INDEX(ModelOutput!$D$16:$D$26,MATCH($A19,ModelOutput!$C$16:$C$26,0))) -> 1 | K19: =IF($C19="Yes",1,INDEX(ModelOutput!$D$16:$D$26,MATCH($C19,ModelOutput!$C$16:$C$26,0))) -> 1 | L19: =IF($D19="2.0-3.0",1,INDEX(ModelOutput!$D$16:$D$26,MATCH($D19,ModelOutput!$C$16:$C$26,0))) -> 1 | M19: =IF($B19="On campus",1,INDEX(ModelOutput!$D$16:$D$26,MATCH($B19,ModelOutput!$C$16:$C$26,0))) -> 1 | N19: =IF($B19="On campus",1,INDEX(ModelOutput!$E$16:$E$26,MATCH($B19,ModelOutput!$C$16:$C$26,0))) -> 1 | O19: =IF($B19="On campus",1,INDEX(ModelOutput!$F$16:$F$26,MATCH($B19,ModelOutput!$C$16:$C$26,0))) -> 1 | P19: =IF($B19="On campus",1,INDEX(ModelOutput!$G$16:$G$26,MATCH($B19,ModelOutput!$C$16:$C$26,0))) -> 1 | Q19: =INDEX(ModelOutput!$D$9:$D$11,MATCH("Tier "&$F19,ModelOutput!$B$9:$B$11,0)) -> 40.009437 | R19: =INDEX(ModelOutput!$E$9:$E$11,MATCH("Tier "&$F19,ModelOutput!$B$9:$B$11,0)) -> 117.94972 | S19: =INDEX(ModelOutput!$F$9:$F$11,MATCH("Tier "&$F19,ModelOutput!$B$9:$B$11,0)) -> 136.83923 | T19: =INDEX(ModelOutput!$G$9:$G$11,MATCH("Tier "&$F19,ModelOutput!$B$9:$B$11,0)) -> 22.729632 | U19: =$Q19*$I19*$J19*$K19*$L19*$M19 -> 47.638454 | V19: =$R19*$I19*$J19*$K19*$L19*$N19 -> 140.44043 | W19: =$S19*$I19*$J19*$K19*$L19*$O19 -> 162.93179 | X19: =$T19*$I19*$J19*$K19*$L19*$P19 -> 27.063727 | Y19: =SUM(U19:X19) -> 378.0744 | Z19: =$Y19*GROSS_MULT+POLICY_FEE -> 656.44511 | AA19: =$Z19/CURRENT_FLAT-1 -> -0.53973398 | AB19: =MEDIAN(CURRENT_FLAT*(1-CAP_DOWN),$Z19,CURRENT_FLAT*(1+CAP_UP)) -> 1069.6723 | AC19: =IF($Z19>CURRENT_FLAT,ROUNDUP(LN($Z19/CURRENT_FLAT)/LN(1+CAP_UP),0),IF($Z19<CURRENT_FLAT,ROUNDUP(LN($Z19/CURRENT_FLAT)/LN(1-CAP_DOWN),0),0)) -> 3 | AD19: 378.0744 | AE19: =$Y19-$AD19 -> -6.2527761e-13 | AF19: =IF($E19="Freshman",4,IF($E19="Sophomore",3,IF($E19="Junior",2,IF($E19="Senior",1,2)))) -> 2
... A404: Greek | B404: Off 6+mi | C404: No | D404: 3.0+ | E404: Grad student | F404: 3 | G404: Grad | H404: 0 | I404: =IF($G404="Base",1,INDEX(ModelOutput!$D$16:$D$26,MATCH($G404,ModelOutput!$C$16:$C$26,0))) -> 1.1906804 | J404: =IF($A404="Non-greek",1,INDEX(ModelOutput!$D$16:$D$26,MATCH($A404,ModelOutput!$C$16:$C$26,0))) -> 4.3562312 | K404: =IF($C404="Yes",1,INDEX(ModelOutput!$D$16:$D$26,MATCH($C404,ModelOutput!$C$16:$C$26,0))) -> 1.5400748 | L404: =IF($D404="2.0-3.0",1,INDEX(ModelOutput!$D$16:$D$26,MATCH($D404,ModelOutput!$C$16:$C$26,0))) -> 0.87654762 | M404: =IF($B404="On campus",1,INDEX(ModelOutput!$D$16:$D$26,MATCH($B404,ModelOutput!$C$16:$C$26,0))) -> 2.2239289 | N404: =IF($B404="On campus",1,INDEX(ModelOutput!$E$16:$E$26,MATCH($B404,ModelOutput!$C$16:$C$26,0))) -> 2.1888545 | O404: =IF($B404="On campus",1,INDEX(ModelOutput!$F$16:$F$26,MATCH($B404,ModelOutput!$C$16:$C$26,0))) -> 2.8272586 | P404: =IF($B404="On campus",1,INDEX(ModelOutput!$G$16:$G$26,MATCH($B404,ModelOutput!$C$16:$C$26,0))) -> 3.5639395 | Q404: =INDEX(ModelOutput!$D$9:$D$11,MATCH("Tier "&$F404,ModelOutput!$B$9:$B$11,0)) -> 40.009437 | R404: =INDEX(ModelOutput!$E$9:$E$11,MATCH("Tier "&$F404,ModelOutput!$B$9:$B$11,0)) -> 117.94972 | S404: =INDEX(ModelOutput!$F$9:$F$11,MATCH("Tier "&$F404,ModelOutput!$B$9:$B$11,0)) -> 136.83923 | T404: =INDEX(ModelOutput!$G$9:$G$11,MATCH("Tier "&$F404,ModelOutput!$B$9:$B$11,0)) -> 22.729632 | U404: =$Q404*$I404*$J404*$K404*$L404*$M404 -> 623.0269 | V404: =$R404*$I404*$J404*$K404*$L404*$N404 -> 1807.7454 | W404: =$S404*$I404*$J404*$K404*$L404*$O404 -> 2708.9413 | X404: =$T404*$I404*$J404*$K404*$L404*$P404 -> 567.21299 | Y404: =SUM(U404:X404) -> 5706.9266 | Z404: =$Y404*GROSS_MULT+POLICY_FEE -> 9321.5742 | AA404: =$Z404/CURRENT_FLAT-1 -> 5.5358152 | AB404: =MEDIAN(CURRENT_FLAT*(1-CAP_DOWN),$Z404,CURRENT_FLAT*(1+CAP_UP)) -> 1782.7872 | AC404: =IF($Z404>CURRENT_FLAT,ROUNDUP(LN($Z404/CURRENT_FLAT)/LN(1+CAP_UP),0),IF($Z404<CURRENT_FLAT,ROUNDUP(LN($Z404/CURRENT_FLAT)/LN(1-CAP_DOWN),0),0)) -> 9 | AD404: 5706.9266 | AE404: =$Y404-$AD404 -> 0 | AF404: =IF($E404="Freshman",4,IF($E404="Sophomore",3,IF($E404="Junior",2,IF($E404="Senior",1,2)))) -> 2

Sheet Dislocation
B2: Dislocation & Capping
B3: How far each student moves off today's flat premium, and what capping that move costs.
B4: Today's flat premium is not given in the case. We use the average indicated.
B6: PREMIUM CHANGE DISTRIBUTION
B7: Change vs today | C7: Students | D7: Share of book | E7: Avg new premium | F7: Premium $
B8: Decrease > 50% | C8: =SUMIFS(Segments!$H$5:$H$404,Segments!$AA$5:$AA$404,"<-0.5") -> 3821 | D8: =C8/$C$16 -> 0.3821 | E8: =IFERROR(SUMPRODUCT(Segments!$H$5:$H$404,Segments!$Z$5:$Z$404,--(Segments!$AA$5:$AA$404<-0.5))/SUMPRODUCT(Segments!$H$5:$H$404,--(Segments!$AA$5:$AA$404<-0.5)),0) -> 548.89174 | F8: =SUMPRODUCT(Segments!$H$5:$H$404,Segments!$Z$5:$Z$404,--(Segments!$AA$5:$AA$404<-0.5)) -> 2097315.3
B9: Decrease 25-50% | C9: =SUMIFS(Segments!$H$5:$H$404,Segments!$AA$5:$AA$404,">=-0.5",Segments!$AA$5:$AA$404,"<-0.25") -> 1881 | D9: =C9/$C$16 -> 0.1881 | E9: =IFERROR(SUMPRODUCT(Segments!$H$5:$H$404,Segments!$Z$5:$Z$404,--(Segments!$AA$5:$AA$404>=-0.5)*--(Segments!$AA$5:$AA$404<-0.25))/SUMPRODUCT(Segments!$H$5:$H$404,--(Segments!$AA$5:$AA$404>=-0.5)*--(Segments!$AA$5:$AA$404<-0.25)),0) -> 866.1028 | F9: =SUMPRODUCT(Segments!$H$5:$H$404,Segments!$Z$5:$Z$404,--(Segments!$AA$5:$AA$404>=-0.5)*--(Segments!$AA$5:$AA$404<-0.25)) -> 1629139.4
B10: Decrease 10-25% | C10: =SUMIFS(Segments!$H$5:$H$404,Segments!$AA$5:$AA$404,">=-0.25",Segments!$AA$5:$AA$404,"<-0.1") -> 1034 | D10: =C10/$C$16 -> 0.1034 | E10: =IFERROR(SUMPRODUCT(Segments!$H$5:$H$404,Segments!$Z$5:$Z$404,--(Segments!$AA$5:$AA$404>=-0.25)*--(Segments!$AA$5:$AA$404<-0.1))/SUMPRODUCT(Segments!$H$5:$H$404,--(Segments!$AA$5:$AA$404>=-0.25)*--(Segments!$AA$5:$AA$404<-0.1)),0) -> 1163.0343 | F10: =SUMPRODUCT(Segments!$H$5:$H$404,Segments!$Z$5:$Z$404,--(Segments!$AA$5:$AA$404>=-0.25)*--(Segments!$AA$5:$AA$404<-0.1)) -> 1202577.4
B11: Within +/-10% | C11: =SUMIFS(Segments!$H$5:$H$404,Segments!$AA$5:$AA$404,">=-0.1",Segments!$AA$5:$AA$404,"<0.1") -> 579 | D11: =C11/$C$16 -> 0.0579 | E11: =IFERROR(SUMPRODUCT(Segments!$H$5:$H$404,Segments!$Z$5:$Z$404,--(Segments!$AA$5:$AA$404>=-0.1)*--(Segments!$AA$5:$AA$404<0.1))/SUMPRODUCT(Segments!$H$5:$H$404,--(Segments!$AA$5:$AA$404>=-0.1)*--(Segments!$AA$5:$AA$404<0.1)),0) -> 1397.6264 | F11: =SUMPRODUCT(Segments!$H$5:$H$404,Segments!$Z$5:$Z$404,--(Segments!$AA$5:$AA$404>=-0.1)*--(Segments!$AA$5:$AA$404<0.1)) -> 809225.69
B12: Increase 10-25% | C12: =SUMIFS(Segments!$H$5:$H$404,Segments!$AA$5:$AA$404,">=0.1",Segments!$AA$5:$AA$404,"<0.25") -> 334 | D12: =C12/$C$16 -> 0.0334 | E12: =IFERROR(SUMPRODUCT(Segments!$H$5:$H$404,Segments!$Z$5:$Z$404,--(Segments!$AA$5:$AA$404>=0.1)*--(Segments!$AA$5:$AA$404<0.25))/SUMPRODUCT(Segments!$H$5:$H$404,--(Segments!$AA$5:$AA$404>=0.1)*--(Segments!$AA$5:$AA$404<0.25)),0) -> 1665.0976 | F12: =SUMPRODUCT(Segments!$H$5:$H$404,Segments!$Z$5:$Z$404,--(Segments!$AA$5:$AA$404>=0.1)*--(Segments!$AA$5:$AA$404<0.25)) -> 556142.6
B13: Increase 25-50% | C13: =SUMIFS(Segments!$H$5:$H$404,Segments!$AA$5:$AA$404,">=0.25",Segments!$AA$5:$AA$404,"<0.5") -> 712 | D13: =C13/$C$16 -> 0.0712 | E13: =IFERROR(SUMPRODUCT(Segments!$H$5:$H$404,Segments!$Z$5:$Z$404,--(Segments!$AA$5:$AA$404>=0.25)*--(Segments!$AA$5:$AA$404<0.5))/SUMPRODUCT(Segments!$H$5:$H$404,--(Segments!$AA$5:$AA$404>=0.25)*--(Segments!$AA$5:$AA$404<0.5)),0) -> 1974.05 | F13: =SUMPRODUCT(Segments!$H$5:$H$404,Segments!$Z$5:$Z$404,--(Segments!$AA$5:$AA$404>=0.25)*--(Segments!$AA$5:$AA$404<0.5)) -> 1405523.6
B14: Increase 50-100% | C14: =SUMIFS(Segments!$H$5:$H$404,Segments!$AA$5:$AA$404,">=0.5",Segments!$AA$5:$AA$404,"<1.0") -> 613 | D14: =C14/$C$16 -> 0.0613 | E14: =IFERROR(SUMPRODUCT(Segments!$H$5:$H$404,Segments!$Z$5:$Z$404,--(Segments!$AA$5:$AA$404>=0.5)*--(Segments!$AA$5:$AA$404<1))/SUMPRODUCT(Segments!$H$5:$H$404,--(Segments!$AA$5:$AA$404>=0.5)*--(Segments!$AA$5:$AA$404<1)),0) -> 2414.4325 | F14: =SUMPRODUCT(Segments!$H$5:$H$404,Segments!$Z$5:$Z$404,--(Segments!$AA$5:$AA$404>=0.5)*--(Segments!$AA$5:$AA$404<1)) -> 1480047.1
B15: Increase > 100% | C15: =SUMIFS(Segments!$H$5:$H$404,Segments!$AA$5:$AA$404,">=1.0") -> 1026 | D15: =C15/$C$16 -> 0.1026 | E15: =IFERROR(SUMPRODUCT(Segments!$H$5:$H$404,Segments!$Z$5:$Z$404,--(Segments!$AA$5:$AA$404>=1))/SUMPRODUCT(Segments!$H$5:$H$404,--(Segments!$AA$5:$AA$404>=1)),0) -> 4953.5347 | F15: =SUMPRODUCT(Segments!$H$5:$H$404,Segments!$Z$5:$Z$404,--(Segments!$AA$5:$AA$404>=1)) -> 5082326.6
B16: TOTAL | C16: =SUM(C8:C15) -> 10000 | D16: =SUM(D8:D15) -> 1 | E16: =SUMPRODUCT(Segments!$H$5:$H$404,Segments!$Z$5:$Z$404)/SUM(Segments!$H$5:$H$404) -> 1426.2298 | F16: =SUMPRODUCT(Segments!$H$5:$H$404,Segments!$Z$5:$Z$404) -> 14262298
B18: WHO MOVES — BY GREEK STATUS AND LOCATION
B19: Segment | C19: Students | D19: Share of book | E19: Avg new premium | F19: Avg change
B20: Greek / Off campus | C20: =SUMPRODUCT(Segments!$H$5:$H$404,--(Segments!$A$5:$A$404="Greek")*--(Segments!$B$5:$B$404<>"On campus")) -> 656 | D20: =C20/SUM(Segments!$H$5:$H$404) -> 0.0656 | E20: =IFERROR(SUMPRODUCT(Segments!$H$5:$H$404,Segments!$Z$5:$Z$404,--(Segments!$A$5:$A$404="Greek")*--(Segments!$B$5:$B$404<>"On campus"))/SUMPRODUCT(Segments!$H$5:$H$404,--(Segments!$A$5:$A$404="Greek")*--(Segments!$B$5:$B$404<>"On campus")),0) -> 5781.6579 | F20: =IFERROR(SUMPRODUCT(Segments!$H$5:$H$404,Segments!$AA$5:$AA$404,--(Segments!$A$5:$A$404="Greek")*--(Segments!$B$5:$B$404<>"On campus"))/SUMPRODUCT(Segments!$H$5:$H$404,--(Segments!$A$5:$A$404="Greek")*--(Segments!$B$5:$B$404<>"On campus")),0) -> 3.0538054
